{"uuid": "d89f71e7-2c9d-489f-bef5-569f8562100d", "children": ["bdd4b316-84d1-421e-8594-ec548afb5d81"], "befores": [{"name": "init_driver", "status": "passed", "start": 1638185014757, "stop": 1638185017170}], "afters": [{"name": "init_driver::0", "status": "broken", "statusDetails": {"message": "urllib3.exceptions.MaxRetryError: HTTPConnectionPool(host='127.0.0.1', port=63658): Max retries exceeded with url: /session/d9cc73e81ea246a95b9198f0e421dc6c/window (Caused by NewConnectionError('<urllib3.connection.HTTPConnection object at 0x7fdec2504b50>: Failed to establish a new connection: [Errno 61] Connection refused'))\n", "trace": "  File \"/Users/dbalasub/Library/Python/3.9/lib/python/site-packages/allure_commons/_allure.py\", line 200, in __call__\n    return self._fixture_function(*args, **kwargs)\n  File \"/Library/Frameworks/Python.framework/Versions/3.9/lib/python3.9/site-packages/_pytest/fixtures.py\", line 941, in _teardown_yield_fixture\n    next(it)\n  File \"/Users/dbalasub/PycharmProjects/pythonProject/TestCases/conftest.py\", line 13, in init_driver\n    web_driver.close()\n  File \"/Users/dbalasub/Library/Python/3.9/lib/python/site-packages/selenium/webdriver/remote/webdriver.py\", line 688, in close\n    self.execute(Command.CLOSE)\n  File \"/Users/dbalasub/Library/Python/3.9/lib/python/site-packages/selenium/webdriver/remote/webdriver.py\", line 319, in execute\n    response = self.command_executor.execute(driver_command, params)\n  File \"/Users/dbalasub/Library/Python/3.9/lib/python/site-packages/selenium/webdriver/remote/remote_connection.py\", line 374, in execute\n    return self._request(command_info[0], url, body=data)\n  File \"/Users/dbalasub/Library/Python/3.9/lib/python/site-packages/selenium/webdriver/remote/remote_connection.py\", line 397, in _request\n    resp = self._conn.request(method, url, body=body, headers=headers)\n  File \"/Users/dbalasub/Library/Python/3.9/lib/python/site-packages/urllib3/request.py\", line 74, in request\n    return self.request_encode_url(\n  File \"/Users/dbalasub/Library/Python/3.9/lib/python/site-packages/urllib3/request.py\", line 96, in request_encode_url\n    return self.urlopen(method, url, **extra_kw)\n  File \"/Users/dbalasub/Library/Python/3.9/lib/python/site-packages/urllib3/poolmanager.py\", line 375, in urlopen\n    response = conn.urlopen(method, u.request_uri, **kw)\n  File \"/Users/dbalasub/Library/Python/3.9/lib/python/site-packages/urllib3/connectionpool.py\", line 783, in urlopen\n    return self.urlopen(\n  File \"/Users/dbalasub/Library/Python/3.9/lib/python/site-packages/urllib3/connectionpool.py\", line 783, in urlopen\n    return self.urlopen(\n  File \"/Users/dbalasub/Library/Python/3.9/lib/python/site-packages/urllib3/connectionpool.py\", line 783, in urlopen\n    return self.urlopen(\n  File \"/Users/dbalasub/Library/Python/3.9/lib/python/site-packages/urllib3/connectionpool.py\", line 755, in urlopen\n    retries = retries.increment(\n  File \"/Users/dbalasub/Library/Python/3.9/lib/python/site-packages/urllib3/util/retry.py\", line 574, in increment\n    raise MaxRetryError(_pool, url, error or ResponseError(cause))\n"}, "start": 1638185418235, "stop": 1638185418240}], "start": 1638185014757, "stop": 1638185418240}